<?xml version="1.0"?><robot name="pepe">
	<link name="0">
		<visual>
			<geometry>
				<cylinder length="0.8419837649748321" radius="0.29990000000000006"/>
			</geometry>
		</visual>
		<collision>
			<geometry>
				<cylinder length="0.8419837649748321" radius="0.29990000000000006"/>
			</geometry>
		</collision>
		<inertial>
			<mass value="0.23790661719488365"/>
			<inertia ixx="0.03" iyy="0.03" izz="0.03" ixy="0" ixz="0" iyx="0"/>
		</inertial>
	</link>
	<link name="11">
		<visual>
			<geometry>
				<cylinder length="1.2998" radius="0.9999"/>
			</geometry>
		</visual>
		<collision>
			<geometry>
				<cylinder length="1.2998" radius="0.9999"/>
			</geometry>
		</collision>
		<inertial>
			<mass value="4.0826254835442075"/>
			<inertia ixx="0.03" iyy="0.03" izz="0.03" ixy="0" ixz="0" iyx="0"/>
		</inertial>
	</link>
	<link name="12">
		<visual>
			<geometry>
				<cylinder length="1.2998" radius="0.9999"/>
			</geometry>
		</visual>
		<collision>
			<geometry>
				<cylinder length="1.2998" radius="0.9999"/>
			</geometry>
		</collision>
		<inertial>
			<mass value="4.0826254835442075"/>
			<inertia ixx="0.03" iyy="0.03" izz="0.03" ixy="0" ixz="0" iyx="0"/>
		</inertial>
	</link>
	<link name="13">
		<visual>
			<geometry>
				<cylinder length="1.2998" radius="0.9999"/>
			</geometry>
		</visual>
		<collision>
			<geometry>
				<cylinder length="1.2998" radius="0.9999"/>
			</geometry>
		</collision>
		<inertial>
			<mass value="4.0826254835442075"/>
			<inertia ixx="0.03" iyy="0.03" izz="0.03" ixy="0" ixz="0" iyx="0"/>
		</inertial>
	</link>
	<joint name="11_to_0" type="revolute">
		<parent link="0"/>
		<child link="11"/>
		<axis xyz="1 0 0"/>
		<limit effort="1" upper="-3.1415" lower="3.1415" velocity="1"/>
		<origin rpy="1.157486616930423 3.9004545320751283 4.39822971502571" xyz="2.7472039961232917 0.934905690572342 1.4842324105200366"/>
	</joint>
	<joint name="12_to_0" type="revolute">
		<parent link="0"/>
		<child link="12"/>
		<axis xyz="1 0 0"/>
		<limit effort="1" upper="-3.1415" lower="3.1415" velocity="1"/>
		<origin rpy="1.7362299253956346 3.9004545320751283 4.39822971502571" xyz="2.7472039961232917 0.934905690572342 1.4842324105200366"/>
	</joint>
	<joint name="13_to_0" type="revolute">
		<parent link="0"/>
		<child link="13"/>
		<axis xyz="1 0 0"/>
		<limit effort="1" upper="-3.1415" lower="3.1415" velocity="1"/>
		<origin rpy="2.314973233860846 3.9004545320751283 4.39822971502571" xyz="2.7472039961232917 0.934905690572342 1.4842324105200366"/>
	</joint>
</robot>
